2019-08-10 19:48:24,135 p=2029 u=ansible |  ERROR! the playbook: myprefered-playbook.yml could not be found
2019-08-10 19:48:40,297 passlib.registry registered 'md5_crypt' handler: <class 'passlib.handlers.md5_crypt.md5_crypt'>
2019-08-10 19:48:40,302 p=2049 u=ansible |  PLAY [create stack] ****************************************************************************************************************************************************
2019-08-10 19:48:40,309 p=2049 u=ansible |  TASK [Gathering Facts] *************************************************************************************************************************************************
2019-08-10 19:48:40,309 p=2049 u=ansible |  Saturday 10 August 2019  19:48:40 +0530 (0:00:00.052)       0:00:00.052 ******* 
2019-08-10 19:48:41,200 p=2049 u=ansible |  ok: [localhost]
2019-08-10 19:48:41,217 p=2049 u=ansible |  TASK [Ansible start date] **********************************************************************************************************************************************
2019-08-10 19:48:41,217 p=2049 u=ansible |  Saturday 10 August 2019  19:48:41 +0530 (0:00:00.908)       0:00:00.961 ******* 
2019-08-10 19:48:41,269 p=2049 u=ansible |  ok: [localhost] => {
    "ansible_date_time.date": "2019-08-10"
}
2019-08-10 19:48:41,311 p=2049 u=ansible |  TASK [ISBC] ************************************************************************************************************************************************************
2019-08-10 19:48:41,311 p=2049 u=ansible |  Saturday 10 August 2019  19:48:41 +0530 (0:00:00.093)       0:00:01.055 ******* 
2019-08-10 19:48:41,830 p=2049 u=ansible |  An exception occurred during task execution. To see the full traceback, use -vvv. The error was: keystoneauth1.exceptions.auth_plugins.MissingRequiredOptions: Auth plugin requires parameters which were not given: auth_url
2019-08-10 19:48:41,830 p=2049 u=ansible |  fatal: [localhost]: FAILED! => {"changed": false, "module_stderr": "Traceback (most recent call last):\n  File \"/home/ansible/.ansible/tmp/ansible-tmp-1565446721.32-146692055810835/AnsiballZ_os_stack.py\", line 114, in <module>\n    _ansiballz_main()\n  File \"/home/ansible/.ansible/tmp/ansible-tmp-1565446721.32-146692055810835/AnsiballZ_os_stack.py\", line 106, in _ansiballz_main\n    invoke_module(zipped_mod, temp_path, ANSIBALLZ_PARAMS)\n  File \"/home/ansible/.ansible/tmp/ansible-tmp-1565446721.32-146692055810835/AnsiballZ_os_stack.py\", line 49, in invoke_module\n    imp.load_module('__main__', mod, module, MOD_DESC)\n  File \"/tmp/ansible_os_stack_payload_Yx0bPe/__main__.py\", line 276, in <module>\n  File \"/tmp/ansible_os_stack_payload_Yx0bPe/__main__.py\", line 238, in main\n  File \"/tmp/ansible_os_stack_payload_Yx0bPe/ansible_os_stack_payload.zip/ansible/module_utils/openstack.py\", line 154, in openstack_cloud_from_module\n  File \"/usr/lib/python2.7/site-packages/openstack/__init__.py\", line 59, in connect\n    options=options, **kwargs)\n  File \"/usr/lib/python2.7/site-packages/openstack/config/__init__.py\", line 36, in get_cloud_region\n    return config.get_one(options=parsed_options, **kwargs)\n  File \"/usr/lib/python2.7/site-packages/openstack/config/loader.py\", line 1077, in get_one\n    auth_plugin = loader.load_from_options(**config['auth'])\n  File \"/usr/lib/python2.7/site-packages/keystoneauth1/loading/base.py\", line 162, in load_from_options\n    raise exceptions.MissingRequiredOptions(missing_required)\nkeystoneauth1.exceptions.auth_plugins.MissingRequiredOptions: Auth plugin requires parameters which were not given: auth_url\n", "module_stdout": "", "msg": "MODULE FAILURE\nSee stdout/stderr for the exact error", "rc": 1}
2019-08-10 19:48:41,830 p=2049 u=ansible |  ...ignoring
2019-08-10 19:48:41,842 p=2049 u=ansible |  TASK [Wait until the active instance pings] ****************************************************************************************************************************
2019-08-10 19:48:41,842 p=2049 u=ansible |  Saturday 10 August 2019  19:48:41 +0530 (0:00:00.530)       0:00:01.586 ******* 
2019-08-10 19:49:14,361 p=2049 u=ansible |   [ERROR]: User interrupted execution

